Workbook

Sheet Power Per Click Simulator
B1: Power Per Click | C1: =FORMATAR_JOGO(TRUNC(N1,2)) -> 4,22 BB | E1: F2P Progression | H1: P2W Progression | N1: =PRODUCT(E11,H13,L12,L18,H17,C19,C26,K31,H35,C30,C32) * IF(C2, 2, 1) * IF(C3, 1.25, 1) -> 4.21737e+39 | P1: Titles | Q1: Progressions | R1: Easy trial Upgrades | S1: Tempest Upgrades | T1: Level | U1: Awakening | V1: Avatar | W1: Avatar Level | X1: Clicks, Trial Easy, Trial medium | Y1: Stars Open | Z1: Defense and tempest | AA1: Enchant Punks | AB1: Index
B2: Gamepass 2x Power | C2: TRUE | E2: Plausible Limit | F2: =N1/'Max Power Per Click'!D44 -> 73.828249 | G2: =IFERROR(__xludf.DUMMYFUNCTION("SPARKLINE(F2, {""charttype"",""bar""; ""max"",1; ""color1"",IF(F2 < 0.3, ""#f44336"", IF(F2 < 0.7, ""#ffeb3b"", ""#4caf50""))})"),"") | H2: Plausible Limit | I2: =N1/'Max Power Per Click'!I44 -> 1.7608725 | J2: =IFERROR(__xludf.DUMMYFUNCTION("SPARKLINE(I2, {""charttype"",""bar""; ""max"",1; ""color1"",IF(I2 < 0.3, ""#f44336"", IF(I2 < 0.7, ""#ffeb3b"", ""#4caf50""))})"),"") | P2: None | Q2: None | R2: None | S2: None | T2: 1 | U2: 1 | V2: None | W2: None | X2: None | Y2: None | Z2: None | AA2: None | AB2: None
B3: Vip | C3: TRUE | E3: Not Plausible Limit | F3: =N1/'Max Power Per Click'!D52 -> 42.185855 | G3: =IFERROR(__xludf.DUMMYFUNCTION("SPARKLINE(F3, {""charttype"",""bar""; ""max"",1; ""color1"",IF(F3 < 0.3, ""#f44336"", IF(F3 < 0.7, ""#ffeb3b"", ""#4caf50""))})"),"") | H3: Not Plausible Limit | I3: =N1/'Max Power Per Click'!I52 -> 0.999961 | J3: =IFERROR(__xludf.DUMMYFUNCTION("SPARKLINE(I3, {""charttype"",""bar""; ""max"",1; ""color1"",IF(I3 < 0.3, ""#f44336"", IF(I3 < 0.7, ""#ffeb3b"", ""#4caf50""))})"),"") | P3: Demon Lord | Q3: 1 | R3: 1 | S3: 1 | T3: 2 | U3: 2 | V3: Ussopa | W3: 1 | X3: I | Y3: I | Z3: I | AA3: Cursed Touch | AB3: 1
N4: 4.2173651e+39 | P4: Black Sword | Q4: 2 | R4: 2 | S4: 2 | T4: 3 | U4: 3 | V4: Fire Fists | W4: 2 | X4: II | Y4: II | Z4: II | AA4: Arcane Sovereignty | AB4: 2
A5: Acessories | D5: Evolve | E5: Multipliers | F5: Gacha | H5: Multipliers | J5: Achievements | L5: Multipliers | P5: Dual Blade | Q5: 3 | R5: 3 | S5: 3 | T5: 4 | U5: 4 | V5: Katakure | W5: 3 | X5: III | Y5: III | Z5: III | AA5: Nature Blessing | AB5: 3
A6: Back | B6: Slime Wings | C6: Secret | D6: 5 | E6: =IF(B6="None",1,IFERROR(VLOOKUP(B6,Data!$D:$K,MATCH(C6,Data!$D$2:$K$2,0),FALSE),1)*(1+MIN(D6*0.05,0.25))) -> 3.4375 | F6: Haki | G6: Secret | H6: =IF(G6 = "None",1,IFERROR(HLOOKUP(G6,Data!$P$2:$W$7,2,FALSE()),1)) -> 10 | J6: Clicks | K6: X | L6: =IF(K6 = "None",1,IFERROR(VLOOKUP(K6,Data!$CD:$CJ,2,FALSE()),1)) -> 3.2331874 | P6: King of Curses | Q6: 4 | R6: 4 | S6: 4 | T6: 5 | U6: 5 | V6: Rogerio | W6: 4 | X6: IV | Y6: IV | Z6: IV | AA6: Ancestral Domain | AB6: 4
A7: Body | B7: Volcano Cape | C7: Secret | D7: 5 | E7: =IF(B7="None",1,IFERROR(VLOOKUP(B7,Data!$D:$K,MATCH(C7,Data!$D$2:$K$2,0),FALSE),1)*(1+MIN(D7*0.05,0.25))) -> 3.4375 | F7: Race | G7: Secret | H7: =IF(G7 = "None",1,IFERROR(HLOOKUP(G7,Data!$P$2:$W$7,3,FALSE()),1)) -> 10 | J7: Star Open | K7: VI | L7: =IF(K7 = "None",1,IFERROR(VLOOKUP(K7,Data!$CD:$CJ,3,FALSE()),1)) -> 1.771561 | Q7: 5 | R7: 5 | S7: 5 | T7: 6 | U7: 6 | V7: Nika Luffe | W7: 5 | X7: V | Y7: V | Z7: V | AB7: 5
A8: Head | B8: Igros Mask | C8: Secret | D8: 5 | E8: =IF(B8="None",1,IFERROR(VLOOKUP(B8,Data!$D:$K,MATCH(C8,Data!$D$2:$K$2,0),FALSE),1)*(1+MIN(D8*0.05,0.25))) -> 3.75 | F8: Dragon Power | G8: Secret | H8: =IF(G8 = "None",1,IFERROR(HLOOKUP(G8,Data!$P$2:$W$7,4,FALSE()),1)) -> 4 | J8: Easy Trial | K8: X | L8: =IF(K8 = "None",1,IFERROR(VLOOKUP(K8,Data!$CD:$CJ,4,FALSE()),1)) -> 1.265 | Q8: 6 | R8: 6 | S8: 6 | T8: 7 | U8: 7 | V8: Mr San | W8: 6 | X8: VI | Y8: VI | Z8: VI | AB8: 6
A9: Mask | B9: Panda Mask | C9: Secret | D9: 5 | E9: =IF(B9="None",1,IFERROR(VLOOKUP(B9,Data!$D:$K,MATCH(C9,Data!$D$2:$K$2,0),FALSE),1)*(1+MIN(D9*0.05,0.25))) -> 3.6 | F9: Slime Power | G9: Secret | H9: =IF(G9 = "None",1,IFERROR(HLOOKUP(G9,Data!$P$2:$W$7,5,FALSE()),1)) -> 10 | J9: Medium Trial | K9: X | L9: =IF(K9 = "None",1,IFERROR(VLOOKUP(K9,Data!$CD:$CJ,5,FALSE()),1)) -> 1.265 | Q9: 7 | R9: 7 | S9: 7 | T9: 8 | U9: 8 | V9: San Geko | W9: 7 | X9: VII | Z9: VII | AB9: 7
A10: Waist | B10: Sorcerer Belt | C10: Secret | D10: 5 | E10: =IF(B10="None",1,IFERROR(VLOOKUP(B10,Data!$D:$K,MATCH(C10,Data!$D$2:$K$2,0),FALSE),1)*(1+MIN(D10*0.05,0.25))) -> 3.4375 | F10: Cursed Technique | G10: Secret | H10: =IF(G10 = "None",1,IFERROR(HLOOKUP(G10,Data!$P$2:$W$7,6,FALSE()),1)) -> 10 | J10: Defense | K10: XX | L10: =IF(K10 = "None",1,IFERROR(VLOOKUP(K10,Data!$CD:$CJ,6,FALSE()),1)) -> 1.8975 | Q10: 8 | R10: 8 | S10: 8 | T10: 9 | U10: 9 | V10: Jeren | W10: 8 | X10: VIII | Z10: VIII | AB10: 8
A11: Total | E11: =TRUNC(PRODUCT(E6:E10),2) -> 548.35 | F11: Cursed Spirit | G11: Secret | H11: =IF(G11 = "None",1,IFERROR(HLOOKUP(G11,Data!P2:W8,7,FALSE()),1)) -> 10 | J11: Tempest Raid | K11: XX | L11: =IF(K11 = "None",1,IFERROR(VLOOKUP(K11,Data!$CD:$CJ,7,FALSE()),1)) -> 1.8975 | Q11: 9 | R11: 9 | S11: 9 | T11: 10 | U11: 10 | V11: Gegota | W11: 9 | X11: IX | Z11: IX | AB11: 9
F12: Hunter Rank | G12: Secret | H12: =IF(G12 = "None",1,IFERROR(HLOOKUP(G12,Data!P2:W43,7,FALSE()),1)) -> 10 | J12: Total | L12: =TRUNC(PRODUCT(L6:L11),2) -> 33 | Q12: 10 | R12: 10 | S12: 10 | T12: 11 | U12: 11 | V12: Brole | W12: 10 | X12: X | Z12: X
F13: Total | H13: =PRODUCT(H6:H12) -> 4000000 | Q13: 11 | R13: 11 | S13: 11 | T13: 12 | U13: 12 | V13: Benymaro | W13: 11 | Z13: XI
A14: Swords | C14: Multipliers | F14: Trial/Tempest Power Upgrades | H14: Multipliers | J14: Skill Tree (World 2) | L14: Multipliers | Q14: 12 | R14: 12 | S14: 12 | T14: 13 | U14: 13 | V14: Milina | W14: 12 | Z14: XII
A15: Sword 1 | B15: Yoru | C15: =IF(B15 = "None",1,IFERROR(VLOOKUP(B15,Data!$AD$2:$AE$8,2,FALSE()),1)) -> 5 | F15: Trial | G15: 20 | H15: =IF(G15 = "None",1,IFERROR(VLOOKUP(G15,Data!CL:CN,2,FALSE()),1)) -> 3 | J15: Start | K15: TRUE | L15: =IF(K15 = TRUE,0.05,0) -> 0.05 | Q15: 13 | R15: 13 | S15: 13 | T15: 14 | U15: 14 | V15: Diablo | W15: 13 | Z15: XIII
A16: Enchant Punk | B16: Ancestral Domain | C16: =IF(B16 = "None",1,IFERROR(VLOOKUP(B16,Data!CW:CX,2,FALSE()),1)) -> 1.75 | F16: Tempest | G16: 20 | H16: =IF(G16 = "None",1,IFERROR(VLOOKUP(G16,Data!CL:CN,3,FALSE()),1)) -> 3 | J16: Power | K16: 5 | L16: =IF(K16 = "None",0,IFERROR(VLOOKUP(K16,Data!CP:CR,2,FALSE())-1,0)) -> 0.75 | Q16: 14 | R16: 14 | S16: 14 | T16: 15 | U16: 15 | V16: Maka | W16: 14 | Z16: XIV
A17: Sword 2 | B17: Yoru | C17: =IF(B17 = "None",1,IFERROR(VLOOKUP(B17,Data!$AD$2:$AE$8,2,FALSE()),1)) -> 5 | F17: Total | H17: =PRODUCT(H15:H16) -> 9 | J17: Insane Power | K17: 3 | L17: =IF(K17 = "None",0,IFERROR(VLOOKUP(K17,Data!CP:CR,3,FALSE())-1,0)) -> 0.6 | Q17: 15 | R17: 15 | S17: 15 | T17: 16 | U17: 16 | V17: Megume | W17: 15 | Z17: XV
A18: Enchant Punk | B18: Ancestral Domain | C18: =IF(B18 = "None",1,IFERROR(VLOOKUP(B18,Data!CW:CX,2,FALSE()),1)) -> 1.75 | J18: Total | L18: =SUM(L15:L17)+1 -> 2.4 | Q18: 16 | R18: 16 | S18: 16 | T18: 17 | U18: 17 | V18: Meguna | W18: 16 | Z18: XVI
A19: Total | C19: =PRODUCT(C15:C18) -> 76.5625 | Q19: 17 | R19: 17 | S19: 17 | T19: 18 | U19: 18 | V19: Baep | W19: 17 | Z19: XVII
Q20: 18 | R20: 18 | S20: 18 | T20: 19 | U20: 19 | V20: Cha Cha | W20: 18 | Z20: XVIII
A21: Progressions | C21: Multipliers | F21: Stats | H21: Multipliers | J21: Units | K21: Power Per Unit | Q21: 19 | R21: 19 | S21: 19 | T21: 20 | U21: 20 | V21: Monarch | W21: 19 | Z21: XIX
A22: Fighting Style | B22: 100 | C22: =IF(B22 = "None",1,IFERROR(VLOOKUP(B22,Data!$Y:$AC,2,FALSE()),1)) -> 3 | F22: Awakening | G22: 36 | H22: =IF(G22 = "None",1,IFERROR(VLOOKUP(G22,Data!A:B,2,FALSE()),1)) -> 34480000000 | J22: Unit 1 | K22: =12300*1.75^3 -> 65920.312 | Q22: 20 | R22: 20 | S22: 20 | T22: 21 | U22: 21 | W22: 20 | Z22: XX
A23: Demon Lord | B23: 100 | C23: =IF(B23 = "None",1,IFERROR(VLOOKUP(B23,Data!$Y:$AC,3,FALSE()),1)) -> 3.5 | F23: Fighters | G23: Kenpache | H23: =IF(G23 = "None",1,IFERROR(VLOOKUP(G23,Data!AG:AH,2,FALSE()),1)) -> 1.5 | J23: Unit 2 | K23: =12300*1.75^3 -> 65920.312 | Q23: 21 | T23: 22 | U23: 22 | W23: 21
A24: Domain | B24: 100 | C24: =IF(B24 = "None",1,IFERROR(VLOOKUP(B24,Data!$Y:$AC,4,FALSE()),1)) -> 3.5 | F24: Fighter 2 | G24: Kenpache | H24: =IF(G24 = "None",1,IFERROR(VLOOKUP(G24,Data!AG:AH,2,FALSE()),1)) -> 1.5 | J24: Unit 3 | K24: =12300*1.75^3 -> 65920.312 | Q24: 22 | T24: 23 | U24: 23 | W24: 22
A25: System | B25: 100 | C25: =IF(B25 = "None",1,IFERROR(VLOOKUP(B25,Data!$Y:$AC,5,FALSE()),1)) -> 3.5 | F25: Title | G25: King of Curses | H25: =IF(G25 = "None",1,IFERROR(VLOOKUP(G25,Data!AJ:AK,2,FALSE()),1)) -> 1.5 | J25: Unit 4 | K25: =12300*1.75^3 -> 65920.312 | Q25: 23 | T25: 24 | U25: 24 | W25: 23
A26: Total | C26: =PRODUCT(C22:C25) -> 128.625 | F26: Index | G26: 9 | H26: =TRUNC(IF(G26 = "None",1,IFERROR(VLOOKUP(G26,Data!M:N,2,FALSE()),1)),2) -> 2.35 | J26: Unit 5 | K26: =12300*1.75^3 -> 65920.312 | Q26: 24 | T26: 25 | U26: 25 | W26: 24
A27: Skill Tree (World 9) | C27: Multipliers | F27: Avatar | G27: Monarch | H27: =ROUND(IF(G27 = "None",1,IFERROR(VLOOKUP(G27,Data!AM:BV,G28+1,FALSE()),1)),2) -> 645.98 | J27: Unit 6 | K27: =12300*1.75^3 -> 65920.312 | Q27: 25 | T27: 26 | U27: 26 | W27: 25
A28: Start | B28: TRUE | C28: =IF(B28 = TRUE,0.1,0) -> 0.1 | F28: Avatar Level | G28: 35 | J28: Unit 7 | K28: =12300*1.75^3 -> 65920.312 | Q28: 26 | T28: 27 | U28: 27 | W28: 26
A29: Power | B29: 10 | C29: =IF(B29 = "None",1,IFERROR(VLOOKUP(B29,Data!CP10:CQ20,2,FALSE())-1,0)) -> 2.4 | F29: Potions | J29: Unit 8 | K29: =12300*1.75^3 -> 65920.312 | Q29: 27 | T29: 28 | U29: 28 | W29: 27
A30: Total | C30: =SUM(C28:C29)+1 -> 3.5 | F30: Power Potion I | G30: TRUE | H30: =IF(G30 = TRUE,1.5,1) -> 1.5 | J30: Unit 9 | K30: =12300*1.75^3 -> 65920.312 | Q30: 28 | T30: 29 | U30: 29 | W30: 28
F31: Power Potion II | G31: TRUE | H31: =IF(G31 = TRUE,2,1) -> 2 | J31: Total | K31: =SUM(K22:K30)+1 -> 593283.81 | Q31: 29 | T31: 30 | U31: 30 | W31: 29
A32: Follow all Devs | B32: TRUE | C32: =IF(B32 = TRUE,1.15^3,1) -> 1.520875 | F32: Power Potion III | G32: TRUE | H32: =IF(G32 = TRUE,2.5,1) -> 2.5 | Q32: 30 | T32: 31 | U32: 31 | W32: 30
F33: Side Quests | G33: 5 | H33: =TRUNC(IF(G33 = "None",1,IFERROR(VLOOKUP(G33,Data!CA:CB,2,FALSE()),1)),2) -> 7.59 | Q33: 31 | T33: 32 | U33: 32 | W33: 31
F34: Level | G34: 50 | H34: =IF(G34 = "None",1,IFERROR(VLOOKUP(G34,Data!CT:CU,2,FALSE()),1)) -> 3.45 | Q34: 32 | T34: 33 | U34: 33 | W34: 32
F35: Total | H35: =PRODUCT(H22:H34) -> 3.46937e+16 | Q35: 33 | T35: 34 | U35: 34 | W35: 33
Q36: 34 | T36: 35 | U36: 35 | W36: 34
Q37: 35 | T37: 36 | U37: 36 | W37: 35
Q38: 36 | T38: 37
Q39: 37 | T39: 38
Q40: 38 | T40: 39
...

Sheet Data
A1: Awakenings | D1: Acessories | M1: Index | P1: Gacha | Y1: Progressions | AD1: Swords | AG1: Fighters | AJ1: Title | AM1: Avatars | BX1: Potions | CA1: Side quests | CD1: Achievements | CL1: Trial/Tempest Upgrades | CP1: Skill Tree | CT1: Level | CW1: Passive Punks
A2: 1 | B2: 1 | E2: Common | F2: Uncommon | G2: Rare | H2: Epic | I2: Legendary | J2: Mythical | K2: Secret | M2: 1 | N2: =1.1 -> 1.1 | Q2: Common | R2: Uncommon | S2: Rare | T2: Epic | U2: Legendary | V2: Mythical | W2: Secret | Y2: Levels | Z2: Fighting Style | AA2: Demon Lord | AB2: Domain | AC2: System | AD2: Saw Blade | AE2: 1.15 | AG2: Sakamote | AH2: 1 | AJ2: Demon Lord | AK2: 1.15 | AN2: 1 | AO2: 2 | AP2: 3 | AQ2: 4 | AR2: 5 | AS2: 6 | AT2: 7 | AU2: 8 | AV2: 9 | AW2: 10 | AX2: 11 | AY2: 12 | AZ2: 13 | BA2: 14 | BB2: 15 | BC2: 16 | BD2: 17 | BE2: 18 | BF2: 19 | BG2: 20 | BH2: 21 | BI2: 22 | BJ2: 23 | BK2: 24 | BL2: 25 | BM2: 26 | BN2: 27 | BO2: 28 | BP2: 29 | BQ2: 30 | BR2: 31 | BS2: 32 | BT2: 33 | BU2: 34 | BV2: 35 | BX2: Power Potion I | BY2: 1.5 | CA2: 1 | CB2: =1.5 -> 1.5 | CD2: Level | CE2: Clicks | CF2: Stars Open | CG2: Easy Trials | CH2: Medium trials | CI2: Dragon Defense | CJ2: Tempest Raid | CL2: Levels | CM2: Trial | CN2: Tempest | CP2: Levels | CQ2: Power | CR2: Insane Power | CT2: 1 | CU2: 1 | CW2: Cursed Touch | CX2: 1.25
A3: 2 | B3: 1.5 | D3: Admiral Cape | E3: 1.05 | F3: 1.16 | G3: 1.31 | H3: 1.47 | I3: 1.68 | J3: 1.94 | K3: 2.63 | M3: 2 | N3: =N2*1.1 -> 1.21 | P3: Haki | Q3: 1.1 | R3: 1.25 | S3: 1.5 | T3: 2 | U3: 3.5 | V3: 5 | W3: 10 | Y3: 1 | Z3: =1.02 -> 1.02 | AA3: 1.02 | AB3: 1.02 | AC3: 1.02 | AD3: Blood Scythe | AE3: 1.25 | AG3: Ayanokoje | AH3: 1 | AJ3: Black Sword | AK3: 1.2 | AM3: Ussopa | AN3: 1.25 | AO3: 1.34 | AP3: 1.44 | AQ3: 1.55 | AR3: 1.66 | AS3: 1.79 | AT3: 1.92 | AU3: 2.07 | AV3: 2.22 | AW3: 2.39 | AX3: 2.57 | AY3: 2.76 | AZ3: 2.97 | BA3: 3.19 | BB3: 3.43 | BC3: 3.69 | BD3: 3.96 | BE3: 4.26 | BF3: 4.58 | BG3: 4.93 | BH3: 5.29 | BI3: 5.69 | BJ3: 6.12 | BK3: 6.58 | BL3: 7.07 | BM3: 7.6 | BN3: 8.17 | BO3: 8.78 | BP3: 9.44 | BQ3: 10.15 | BR3: 10.91 | BS3: 11.73 | BT3: 12.61 | BU3: 13.56 | BV3: 14.57 | BX3: Power Potion II | BY3: 2 | CA3: 2 | CB3: =1.5^2 -> 2.25 | CD3: I | CE3: 1.1 | CF3: =1.1 -> 1.1 | CG3: 1 | CH3: 1 | CI3: 1 | CJ3: 1 | CL3: 1 | CM3: 1.1 | CN3: 1.1 | CP3: 1 | CQ3: 1.15 | CR3: 1.2 | CT3: 2 | CU3: =CU2+0.05 -> 1.05 | CW3: Arcane Sovereignty | CX3: 1.35
A4: 3 | B4: 2 | D4: Slime Wings | E4: 1.1 | F4: 1.21 | G4: 1.38 | H4: 1.54 | I4: 1.76 | J4: 2.04 | K4: 2.75 | M4: 3 | N4: =N3*1.1 -> 1.331 | P4: Race | Q4: 1.1 | R4: 1.25 | S4: 1.5 | T4: 2 | U4: 3.5 | V4: 5 | W4: 10 | Y4: 2 | Z4: =Z3+0.02 -> 1.04 | AA4: 1.05 | AB4: 1.05 | AC4: 1.05 | AD4: Lostvayne | AE4: 1.5 | AG4: Seika | AH4: 1 | AJ4: Dual Blade | AK4: 1.3 | AM4: Fire Fists | AN4: 1.5 | AO4: 1.61 | AP4: 1.73 | AQ4: 1.86 | AR4: 2 | AS4: 2.15 | AT4: 2.31 | AU4: 2.49 | AV4: 2.68 | AW4: 2.88 | AX4: 3.09 | AY4: 3.32 | AZ4: 3.57 | BA4: 3.84 | BB4: 4.13 | BC4: 4.44 | BD4: 4.77 | BE4: 5.13 | BF4: 5.51 | BG4: 5.93 | BH4: 6.37 | BI4: 6.85 | BJ4: 7.36 | BK4: 7.92 | BL4: 8.51 | BM4: 9.15 | BN4: 9.83 | BO4: 10.57 | BP4: 11.36 | BQ4: 12.22 | BR4: 13.13 | BS4: 14.12 | BT4: 15.18 | BU4: 16.31 | BV4: 17.54 | BX4: Power Potion III | BY4: 2.5 | CA4: 3 | CB4: =1.5^3 -> 3.375 | CD4: II | CE4: =CE3*1.1 -> 1.21 | CF4: =CF3*1.1 -> 1.21 | CG4: 1 | CH4: 1 | CI4: 1 | CJ4: 1 | CL4: 2 | CM4: 1.2 | CN4: 1.2 | CP4: 2 | CQ4: =1.3 -> 1.3 | CR4: 1.4 | CT4: 3 | CU4: =CU3+0.05 -> 1.1 | CW4: Nature Blessing | CX4: 1.5
A5: 4 | B5: =B4*2 -> 4 | D5: Saiyan Armor | E5: 1.05 | F5: 1.16 | G5: 1.31 | H5: 1.47 | I5: 1.68 | J5: 1.94 | K5: 2.63 | M5: 4 | N5: =N4*1.1 -> 1.4641 | P5: Dragon Power | Q5: 1.05 | R5: 1.1 | S5: 1.15 | T5: 1.25 | U5: 1.5 | V5: 2 | W5: 4 | Y5: 3 | Z5: =Z4+0.02 -> 1.06 | AA5: 1.08 | AB5: 1.08 | AC5: 1.08 | AD5: Bisento | AE5: 1.75 | AG5: Jenos | AH5: 1 | AJ5: King of Curses | AK5: 1.5 | AM5: Katakure | AN5: 1.75 | AO5: 1.88 | AP5: 2.02 | AQ5: 2.17 | AR5: 2.34 | AS5: 2.51 | AT5: 2.7 | AU5: 2.9 | AV5: 3.12 | AW5: 3.36 | AX5: 3.61 | AY5: 3.88 | AZ5: 4.17 | BA5: 4.48 | BB5: 4.82 | BC5: 5.18 | BD5: 5.57 | BE5: 5.98 | BF5: 6.43 | BG5: 6.92 | BH5: 7.43 | BI5: 7.99 | BJ5: 8.59 | BK5: 9.23 | BL5: 9.93 | BM5: 10.67 | BN5: 11.47 | BO5: 12.33 | BP5: 13.26 | BQ5: 14.25 | BR5: 15.32 | BS5: 16.47 | BT5: 17.71 | BU5: 19.03 | BV5: 20.46 | CA5: 4 | CB5: =1.5^4 -> 5.0625 | CD5: III | CE5: =CE4*1.1 -> 1.331 | CF5: =CF4*1.1 -> 1.331 | CG5: 1.1 | CH5: 1.1 | CI5: 1.1 | CJ5: 1.1 | CL5: 3 | CM5: 1.3 | CN5: 1.3 | CP5: 3 | CQ5: 1.45 | CR5: 1.6 | CT5: 4 | CU5: =CU4+0.05 -> 1.15 | CW5: Ancestral Domain | CX5: 1.75
A6: 5 | B6: =B5*2 -> 8 | D6: Volcano Cape | E6: 1.1 | F6: 1.21 | G6: 1.38 | H6: 1.54 | I6: 1.76 | J6: 2.04 | K6: 2.75 | M6: 5 | N6: =N5*1.1 -> 1.61051 | P6: Slime Power | Q6: 1.1 | R6: 1.25 | S6: 1.5 | T6: 2 | U6: 3.5 | V6: 5 | W6: 10 | Y6: 4 | Z6: =Z5+0.02 -> 1.08 | AA6: 1.1 | AB6: 1.1 | AC6: 1.1 | AD6: Uzue Blade | AE6: 2 | AG6: Sankoji | AH6: 1.1 | AM6: Rogerio | AN6: 2 | AO6: 2.15 | AP6: 2.31 | AQ6: 2.48 | AR6: 2.67 | AS6: 2.87 | AT6: 3.09 | AU6: 3.32 | AV6: 3.57 | AW6: 3.83 | AX6: 4.12 | AY6: 4.43 | AZ6: 4.76 | BA6: 5.12 | BB6: 5.5 | BC6: 5.92 | BD6: 6.36 | BE6: 6.84 | BF6: 7.35 | BG6: 7.9 | BH6: 8.5 | BI6: 9.13 | BJ6: 9.82 | BK6: 10.55 | BL6: 11.35 | BM6: 12.2 | BN6: 13.11 | BO6: 14.09 | BP6: 15.15 | BQ6: 16.29 | BR6: 17.51 | BS6: 18.82 | BT6: 20.23 | BU6: 21.75 | BV6: 23.38 | CA6: 5 | CB6: =1.5^5 -> 7.59375 | CD6: IV | CE6: =CE5*1.1 -> 1.4641 | CF6: =CF5*1.1 -> 1.4641 | CG6: 1.1 | CH6: 1.1 | CI6: 1.1 | CJ6: 1.1 | CL6: 4 | CM6: 1.4 | CN6: 1.4 | CP6: 4 | CQ6: 1.6 | CT6: 5 | CU6: =CU5+0.05 -> 1.2
A7: 6 | B7: =B6*2 -> 16 | D7: Cute Slime | E7: 1.1 | F7: 1.21 | G7: 1.38 | H7: 1.54 | I7: 1.76 | J7: 2.04 | K7: 2.75 | M7: 6 | N7: =N6*1.1 -> 1.771561 | P7: Cursed Technique | Q7: 1.1 | R7: 1.25 | S7: 1.5 | T7: 2 | U7: 3.5 | V7: 5 | W7: 10 | Y7: 5 | Z7: =Z6+0.02 -> 1.1 | AA7: 1.13 | AB7: 1.13 | AC7: 1.13 | AD7: King Spear | AE7: 2.5 | AG7: Power | AH7: 1.25 | AM7: Nika Luffe | AN7: 4.5 | AO7: 4.84 | AP7: 5.2 | AQ7: 5.59 | AR7: 6.01 | AS7: 6.46 | AT7: 6.94 | AU7: 7.47 | AV7: 8.03 | AW7: 8.63 | AX7: 9.27 | AY7: 9.97 | AZ7: 10.72 | BA7: 11.52 | BB7: 12.39 | BC7: 13.31 | BD7: 14.31 | BE7: 15.39 | BF7: 16.54 | BG7: 17.78 | BH7: 19.12 | BI7: 20.55 | BJ7: 22.09 | BK7: 23.75 | BL7: 25.53 | BM7: 27.44 | BN7: 29.5 | BO7: 31.71 | BP7: 34.09 | BQ7: 36.65 | BR7: 39.4 | BS7: 42.35 | BT7: 45.53 | BU7: 48.94 | BV7: 52.61 | CD7: V | CE7: =CE6*1.1 -> 1.61051 | CF7: =CF6*1.1 -> 1.61051 | CG7: 1.1 | CH7: 1.1 | CI7: 1.1 | CJ7: 1.1 | CL7: 5 | CM7: 1.5 | CN7: 1.5 | CP7: 5 | CQ7: 1.75 | CT7: 6 | CU7: =CU6+0.05 -> 1.25
A8: 7 | B8: =B7*2 -> 32 | D8: Fire Hat | E8: 1.05 | F8: 1.16 | G8: 1.31 | H8: 1.47 | I8: 1.68 | J8: 1.94 | K8: 2.63 | M8: 7 | N8: =N7*1.1 -> 1.9487171 | P8: Cursed Spirit | Q8: 1.1 | R8: 1.25 | S8: 1.5 | T8: 2 | U8: 3.5 | V8: 5 | W8: 10 | Y8: 6 | Z8: =Z7+0.02 -> 1.12 | AA8: 1.15 | AB8: 1.15 | AC8: 1.15 | AD8: Yoru | AE8: 5 | AG8: Kenpache | AH8: 1.5 | AM8: Mr San | AN8: 2.35 | AO8: 2.53 | AP8: 2.72 | AQ8: 2.92 | AR8: 3.14 | AS8: 3.37 | AT8: 3.63 | AU8: 3.9 | AV8: 4.19 | AW8: 4.51 | AX8: 4.84 | AY8: 5.21 | AZ8: 5.6 | BA8: 6.02 | BB8: 6.47 | BC8: 6.95 | BD8: 7.47 | BE8: 8.04 | BF8: 8.64 | BG8: 9.29 | BH8: 9.98 | BI8: 10.73 | BJ8: 11.54 | BK8: 12.4 | BL8: 13.33 | BM8: 14.33 | BN8: 15.41 | BO8: 16.56 | BP8: 17.8 | BQ8: 19.14 | BR8: 20.57 | BS8: 22.12 | BT8: 23.78 | BU8: 25.56 | BV8: 27.48 | CD8: VI | CE8: =CE7*1.1 -> 1.771561 | CF8: =CF7*1.1 -> 1.771561 | CG8: 1.1 | CH8: 1.1 | CI8: 1.1 | CJ8: 1.1 | CL8: 6 | CM8: 1.6 | CN8: 1.6 | CT8: 7 | CU8: =CU7+0.05 -> 1.3
A9: 8 | B9: =B8*2 -> 64 | D9: Oatmeel | E9: 1.05 | F9: 1.16 | G9: 1.31 | H9: 1.47 | I9: 1.68 | J9: 1.94 | K9: 2.63 | M9: 8 | N9: =N8*1.1 -> 2.1435888 | P9: Hunter Rank | Q9: 1.1 | R9: 1.25 | S9: 1.5 | T9: 2 | U9: 3.5 | V9: 5 | W9: 10 | Y9: 7 | Z9: =Z8+0.02 -> 1.14 | AA9: 1.18 | AB9: 1.18 | AC9: 1.18 | AM9: San Geko | AN9: 2.7 | AO9: 2.9 | AP9: 3.12 | AQ9: 3.35 | AR9: 3.61 | AS9: 3.88 | AT9: 4.17 | AU9: 4.48 | AV9: 4.82 | AW9: 5.18 | AX9: 5.56 | AY9: 5.98 | AZ9: 6.43 | BA9: 6.91 | BB9: 7.43 | BC9: 7.99 | BD9: 8.59 | BE9: 9.23 | BF9: 9.92 | BG9: 10.67 | BH9: 11.47 | BI9: 12.33 | BJ9: 13.25 | BK9: 14.25 | BL9: 15.32 | BM9: 16.47 | BN9: 17.7 | BO9: 19.03 | BP9: 20.46 | BQ9: 21.99 | BR9: 23.64 | BS9: 25.41 | BT9: 27.32 | BU9: 29.37 | BV9: 31.57 | CD9: VII | CE9: =CE8*1.15 -> 2.0372951 | CG9: 1.1 | CH9: 1.1 | CI9: 1.1 | CJ9: 1.1 | CL9: 7 | CM9: 1.7 | CN9: 1.7 | CP9: Skill Tree (W9) | CT9: 8 | CU9: =CU8+0.05 -> 1.35
A10: 9 | B10: =B9*2 -> 128 | D10: Rimuro Mask | E10: 1.1 | F10: 1.21 | G10: 1.38 | H10: 1.54 | I10: 1.76 | J10: 2.04 | K10: 2.75 | M10: 9 | N10: =N9*1.1 -> 2.3579477 | Y10: 8 | Z10: =Z9+0.02 -> 1.16 | AA10: 1.2 | AB10: 1.2 | AC10: 1.2 | AM10: Jeren | AN10: 3.05 | AO10: 3.28 | AP10: 3.52 | AQ10: 3.79 | AR10: 4.07 | AS10: 4.38 | AT10: 4.71 | AU10: 5.06 | AV10: 5.44 | AW10: 5.85 | AX10: 6.29 | AY10: 6.76 | AZ10: 7.26 | BA10: 7.81 | BB10: 8.39 | BC10: 9.02 | BD10: 9.7 | BE10: 10.43 | BF10: 11.21 | BG10: 12.05 | BH10: 12.96 | BI10: 13.93 | BJ10: 14.97 | BK10: 16.1 | BL10: 17.3 | BM10: 18.6 | BN10: 19.99 | BO10: 21.49 | BP10: 23.11 | BQ10: 24.84 | BR10: 26.7 | BS10: 28.71 | BT10: 30.86 | BU10: 33.17 | BV10: 35.66 | CD10: VIII | CE10: =CE9*1.15 -> 2.3428894 | CG10: =1.1*1.15 -> 1.265 | CH10: 1.265 | CI10: 1.265 | CJ10: 1.265 | CL10: 8 | CM10: 1.8 | CN10: 1.8 | CP10: Levels | CQ10: Power | CT10: 9 | CU10: =CU9+0.05 -> 1.4
A11: 10 | B11: =B10*2 -> 256 | D11: Zama Mask | E11: 1.05 | F11: 1.16 | G11: 1.31 | H11: 1.47 | I11: 1.68 | J11: 1.94 | K11: 2.63 | Y11: 9 | Z11: =Z10+0.02 -> 1.18 | AA11: 1.23 | AB11: 1.23 | AC11: 1.23 | AM11: Gegota | AN11: 3.4 | AO11: 3.66 | AP11: 3.93 | AQ11: 4.22 | AR11: 4.54 | AS11: 4.88 | AT11: 5.25 | AU11: 5.64 | AV11: 6.06 | AW11: 6.52 | AX11: 7.01 | AY11: 7.53 | AZ11: 8.1 | BA11: 8.71 | BB11: 9.36 | BC11: 10.06 | BD11: 10.81 | BE11: 11.63 | BF11: 12.5 | BG11: 13.44 | BH11: 14.44 | BI11: 15.53 | BJ11: 16.69 | BK11: 17.94 | BL11: 19.29 | BM11: 20.73 | BN11: 22.29 | BO11: 23.96 | BP11: 25.76 | BQ11: 27.69 | BR11: 29.77 | BS11: 32 | BT11: 34.4 | BU11: 36.98 | BV11: 39.75 | CD11: IX | CE11: =CE10*1.15 -> 2.6943228 | CG11: 1.265 | CH11: 1.265 | CI11: 1.265 | CJ11: 1.265 | CL11: 9 | CM11: 1.9 | CN11: 1.9 | CP11: 1 | CQ11: 1.2 | CT11: 10 | CU11: =CU10+0.05 -> 1.45
A12: 11 | B12: =B11*2 -> 512 | D12: Sorcerer Belt | E12: 1.1 | F12: 1.21 | G12: 1.38 | H12: 1.54 | I12: 1.76 | J12: 2.04 | K12: 2.75 | Y12: 10 | Z12: =Z11+0.02 -> 1.2 | AA12: 1.25 | AB12: 1.25 | AC12: 1.25 | AM12: Brole | AN12: 7.05 | AO12: 7.58 | AP12: 8.15 | AQ12: 8.76 | AR12: 9.42 | AS12: 10.12 | AT12: 10.88 | AU12: 11.7 | AV12: 12.57 | AW12: 13.52 | AX12: 14.53 | AY12: 15.62 | AZ12: 16.79 | BA12: 18.05 | BB12: 19.4 | BC12: 20.86 | BD12: 22.42 | BE12: 24.11 | BF12: 25.91 | BG12: 27.86 | BH12: 29.95 | BI12: 32.19 | BJ12: 34.61 | BK12: 37.2 | BL12: 39.99 | BM12: 42.99 | BN12: 46.22 | BO12: 49.68 | BP12: 53.41 | BQ12: 57.42 | BR12: 61.72 | BS12: 66.35 | BT12: 71.33 | BU12: 76.68 | BV12: 82.43 | CD12: X | CE12: =CE11*1.2 -> 3.2331874 | CG12: 1.265 | CH12: 1.265 | CI12: 1.265 | CJ12: 1.265 | CL12: 10 | CM12: 2 | CN12: 2 | CP12: 2 | CQ12: =1.4 -> 1.4 | CT12: 11 | CU12: =CU11+0.05 -> 1.5
A13: 12 | B13: =B12*2 -> 1024 | D13: Saiyan Tail | E13: 1.05 | F13: 1.16 | G13: 1.31 | H13: 1.47 | I13: 1.68 | J13: 1.94 | K13: 2.63 | Y13: 11 | Z13: =Z12+0.02 -> 1.22 | AA13: 1.28 | AB13: 1.28 | AC13: 1.28 | AM13: Benymaro | AN13: 3.9 | AO13: 4.19 | AP13: 4.51 | AQ13: 4.84 | AR13: 5.21 | AS13: 5.6 | AT13: 6.02 | AU13: 6.47 | AV13: 6.96 | AW13: 7.48 | AX13: 8.04 | AY13: 8.64 | AZ13: 9.29 | BA13: 9.99 | BB13: 10.73 | BC13: 11.54 | BD13: 12.41 | BE13: 13.34 | BF13: 14.34 | BG13: 15.41 | BH13: 16.57 | BI13: 17.81 | BJ13: 19.14 | BK13: 20.58 | BL13: 22.12 | BM13: 23.78 | BN13: 25.57 | BO13: 27.48 | BP13: 29.55 | BQ13: 31.76 | BR13: 34.14 | BS13: 36.71 | BT13: 39.46 | BU13: 42.42 | BV13: 45.6 | CD13: XI | CI13: 1.265 | CJ13: 1.265 | CL13: 11 | CM13: 2.1 | CN13: 2.1 | CP13: 3 | CQ13: =1.6 -> 1.6 | CT13: 12 | CU13: =CU12+0.05 -> 1.55
A14: 13 | B14: =B13*2 -> 2048 | D14: Panda Mask | E14: 1.15 | F14: 1.26 | G14: 1.44 | H14: 1.61 | I14: 1.84 | J14: 2.13 | K14: 2.88 | Y14: 12 | Z14: =Z13+0.02 -> 1.24 | AA14: 1.3 | AB14: 1.3 | AC14: 1.3 | AM14: Milina | AN14: 4.4 | AO14: 4.73 | AP14: 5.08 | AQ14: 5.47 | AR14: 5.88 | AS14: 6.32 | AT14: 6.79 | AU14: 7.3 | AV14: 7.85 | AW14: 8.44 | AX14: 9.07 | AY14: 9.75 | AZ14: 10.48 | BA14: 11.27 | BB14: 12.11 | BC14: 13.02 | BD14: 14 | BE14: 15.05 | BF14: 16.17 | BG14: 17.39 | BH14: 18.69 | BI14: 20.09 | BJ14: 21.6 | BK14: 23.22 | BL14: 24.96 | BM14: 26.83 | BN14: 28.85 | BO14: 31.01 | BP14: 33.33 | BQ14: 35.83 | BR14: 38.52 | BS14: 41.41 | BT14: 44.52 | BU14: 47.86 | BV14: 51.44 | CD14: XII | CI14: 1.265 | CJ14: 1.265 | CL14: 12 | CM14: 2.2 | CN14: 2.2 | CP14: 4 | CQ14: =1.8 -> 1.8 | CT14: 13 | CU14: =CU13+0.05 -> 1.6
A15: 14 | B15: =B14*2 -> 4096 | D15: Dharmachakre | E15: 1.15 | F15: 1.26 | G15: 1.44 | H15: 1.61 | I15: 1.84 | J15: 2.13 | K15: 2.88 | Y15: 13 | Z15: =Z14+0.02 -> 1.26 | AA15: 1.33 | AB15: 1.33 | AC15: 1.33 | AM15: Diablo | AN15: 10.5 | AO15: 11.29 | AP15: 12.13 | AQ15: 13.04 | AR15: 14.02 | AS15: 15.07 | AT15: 16.2 | AU15: 17.42 | AV15: 18.73 | AW15: 20.13 | AX15: 21.64 | AY15: 23.26 | AZ15: 25.01 | BA15: 26.88 | BB15: 28.9 | BC15: 31.07 | BD15: 33.4 | BE15: 35.9 | BF15: 38.6 | BG15: 41.49 | BH15: 44.6 | BI15: 47.95 | BJ15: 51.54 | BK15: 55.41 | BL15: 59.57 | BM15: 64.03 | BN15: 68.84 | BO15: 74 | BP15: 79.55 | BQ15: 85.51 | BR15: 91.93 | BS15: 98.82 | BT15: 106.23 | BU15: 114.2 | BV15: 122.77 | CD15: XIII | CI15: =CI14*1.2 -> 1.518 | CJ15: 1.518 | CL15: 13 | CM15: 2.3 | CN15: 2.3 | CP15: 5 | CQ15: =CQ14+0.25 -> 2.05 | CT15: 14 | CU15: =CU14+0.05 -> 1.65
A16: 15 | B16: =B15*2 -> 8192 | D16: Igros Mask | E16: 1.2 | F16: =E16+0.11 -> 1.31 | G16: =ROUND($E$16*1.25,2) -> 1.5 | H16: =ROUND($E$16*1.4,2) -> 1.68 | I16: =ROUND($E$16*1.6,2) -> 1.92 | J16: =ROUND($E$16*1.85,2) -> 2.22 | K16: =ROUND($E$16*2.5,2) -> 3 | Y16: 14 | Z16: =Z15+0.02 -> 1.28 | AA16: 1.35 | AB16: 1.35 | AC16: 1.35 | AM16: Maka | AN16: 6.6 | AO16: 7.1 | AP16: 7.63 | AQ16: 8.2 | AR16: 8.81 | AS16: 9.48 | AT16: 10.19 | AU16: 10.95 | AV16: 11.77 | AW16: 12.65 | AX16: 13.6 | AY16: 14.62 | AZ16: 15.72 | BA16: 16.9 | BB16: 18.17 | BC16: 19.53 | BD16: 20.99 | BE16: 22.57 | BF16: 24.26 | BG16: 26.08 | BH16: 28.04 | BI16: 30.14 | BJ16: 32.4 | BK16: 34.83 | BL16: 37.44 | BM16: 40.25 | BN16: 43.27 | BO16: 46.51 | BP16: 50 | BQ16: 53.75 | BR16: 57.78 | BS16: 62.12 | BT16: 66.78 | BU16: 71.78 | BV16: 77.17 | CD16: XIV | CI16: 1.518 | CJ16: 1.518 | CL16: 14 | CM16: 2.4 | CN16: 2.4 | CP16: 6 | CQ16: =CQ15+0.25 -> 2.3 | CT16: 15 | CU16: =CU15+0.05 -> 1.7
A17: 16 | B17: =B16*2 -> 16384 | Y17: 15 | Z17: =Z16+0.02 -> 1.3 | AA17: 1.38 | AB17: 1.38 | AC17: 1.38 | AM17: Megume | AN17: 9.15 | AO17: 9.84 | AP17: 10.57 | AQ17: 11.37 | AR17: 12.22 | AS17: 13.14 | AT17: 14.12 | AU17: 15.18 | AV17: 16.32 | AW17: 17.54 | AX17: 18.86 | AY17: 20.27 | AZ17: 21.79 | BA17: 23.43 | BB17: 25.18 | BC17: 27.07 | BD17: 29.1 | BE17: 31.29 | BF17: 33.63 | BG17: 36.16 | BH17: 38.87 | BI17: 41.78 | BJ17: 44.92 | BK17: 48.29 | BL17: 51.91 | BM17: 55.8 | BN17: 59.98 | BO17: 64.48 | BP17: 69.32 | BQ17: 74.52 | BR17: 80.11 | BS17: 86.12 | BT17: 92.57 | BU17: 99.52 | BV17: 106.98 | CD17: XV | CI17: 1.518 | CJ17: 1.518 | CL17: 15 | CM17: 2.5 | CN17: 2.5 | CP17: 7 | CQ17: =CQ16+0.25 -> 2.55 | CT17: 16 | CU17: =CU16+0.05 -> 1.75
A18: 17 | B18: =B17*2 -> 32768 | Y18: 16 | Z18: =Z17+0.02 -> 1.32 | AA18: 1.4 | AB18: 1.4 | AC18: 1.4 | AM18: Meguna | AN18: 25.5 | AO18: 27.41 | AP18: 29.47 | AQ18: 31.68 | AR18: 34.05 | AS18: 36.61 | AT18: 39.35 | AU18: 42.31 | AV18: 45.48 | AW18: 48.89 | AX18: 52.56 | AY18: 56.5 | AZ18: 60.74 | BA18: 65.29 | BB18: 70.19 | BC18: 75.45 | BD18: 81.11 | BE18: 87.19 | BF18: 93.73 | BG18: 100.76 | BH18: 108.32 | BI18: 116.44 | BJ18: 125.18 | BK18: 134.57 | BL18: 144.66 | BM18: 155.51 | BN18: 167.17 | BO18: 179.71 | BP18: 193.19 | BQ18: 207.68 | BR18: 223.25 | BS18: 240 | BT18: 257.99 | BU18: 277.34 | BV18: 298.15 | CD18: XVI | CI18: 1.518 | CJ18: 1.518 | CL18: 16 | CM18: 2.6 | CN18: 2.6 | CP18: 8 | CQ18: =CQ17+0.25 -> 2.8 | CT18: 17 | CU18: =CU17+0.05 -> 1.8
A19: 18 | B19: =B18*2 -> 65536 | D19: V | E19: 3.28 | F19: admiral | H19: Accessory Evolve | Y19: 17 | Z19: =Z18+0.02 -> 1.34 | AA19: 1.43 | AB19: 1.43 | AC19: 1.43 | AM19: Baep | AN19: 12.2 | AO19: =ROUND($AN$19 * 1.075^(AO2-1), 2) -> 13.12 | AP19: =ROUND($AN$19 * 1.075^(AP2-1), 2) -> 14.1 | AQ19: =ROUND($AN$19 * 1.075^(AQ2-1), 2) -> 15.16 | AR19: =ROUND($AN$19 * 1.075^(AR2-1), 2) -> 16.29 | AS19: =ROUND($AN$19 * 1.075^(AS2-1), 2) -> 17.51 | AT19: =ROUND($AN$19 * 1.075^(AT2-1), 2) -> 18.83 | AU19: =ROUND($AN$19 * 1.075^(AU2-1), 2) -> 20.24 | AV19: =ROUND($AN$19 * 1.075^(AV2-1), 2) -> 21.76 | ... BV19: =ROUND($AN$19 * 1.075^(BV2-1), 2) -> 142.64 | CD19: XVII | CI19: 1.518 | CJ19: 1.518 | CL19: 17 | CM19: 2.7 | CN19: 2.7 | CP19: 9 | CQ19: =CQ18+0.3 -> 3.1 | CT19: 18 | CU19: =CU18+0.05 -> 1.85
A20: 19 | B20: =B19*2 -> 131072 | D20: V | E20: 3.75 | F20: igros mask | H20: I | I20: 1.05 | Y20: 18 | Z20: =Z19+0.02 -> 1.36 | AA20: 1.45 | AB20: 1.45 | AC20: 1.45 | AM20: Cha Cha | AN20: 15.4 | AO20: =ROUND($AN$20 * 1.075^(AO2-1), 2) -> 16.56 | AP20: =ROUND($AN$20 * 1.075^(AP2-1), 2) -> 17.8 | AQ20: =ROUND($AN$20 * 1.075^(AQ2-1), 2) -> 19.13 | AR20: =ROUND($AN$20 * 1.075^(AR2-1), 2) -> 20.57 | AS20: =ROUND($AN$20 * 1.075^(AS2-1), 2) -> 22.11 | AT20: =ROUND($AN$20 * 1.075^(AT2-1), 2) -> 23.77 | AU20: =ROUND($AN$20 * 1.075^(AU2-1), 2) -> 25.55 | AV20: =ROUND($AN$20 * 1.075^(AV2-1), 2) -> 27.47 | ... BV20: =ROUND($AN$20 * 1.075^(BV2-1), 2) -> 180.06 | CD20: XVIII | CI20: =CI19*1.25 -> 1.8975 | CJ20: 1.8975 | CL20: 18 | CM20: 2.8 | CN20: 2.8 | CP20: 10 | CQ20: =CQ19+0.3 -> 3.4 | CT20: 19 | CU20: =CU19+0.05 -> 1.9
A21: 20 | B21: =B20*2 -> 262144 | D21: V | E21: 3.44 | F21: sorcerer belt | H21: II | I21: 1.1 | Y21: 19 | Z21: =Z20+0.02 -> 1.38 | AA21: 1.48 | AB21: 1.48 | AC21: 1.48 | AM21: Monarch | AN21: 55.25 | AO21: =ROUND($AN$21 * 1.075^(AO2-1), 2) -> 59.39 | AP21: =ROUND($AN$21 * 1.075^(AP2-1), 2) -> 63.85 | AQ21: =ROUND($AN$21 * 1.075^(AQ2-1), 2) -> 68.64 | AR21: =ROUND($AN$21 * 1.075^(AR2-1), 2) -> 73.78 | AS21: =ROUND($AN$21 * 1.075^(AS2-1), 2) -> 79.32 | AT21: =ROUND($AN$21 * 1.075^(AT2-1), 2) -> 85.27 | AU21: =ROUND($AN$21 * 1.075^(AU2-1), 2) -> 91.66 | AV21: =ROUND($AN$21 * 1.075^(AV2-1), 2) -> 98.54 | ... BV21: =ROUND($AN$21 * 1.075^(BV2-1), 2) -> 645.98 | CD21: XIX | CI21: 1.8975 | CJ21: 1.8975 | CL21: 19 | CM21: 2.9 | CN21: 2.9 | CT21: 20 | CU21: =CU20+0.05 -> 1.95
A22: 21 | B22: =B21*2 -> 524288 | D22: V | E22: 3.59 | F22: panda mask | H22: III | I22: 1.15 | Y22: 20 | Z22: =Z21+0.02 -> 1.4 | AA22: 1.5 | AB22: 1.5 | AC22: 1.5 | CD22: XX | CI22: 1.8975 | CJ22: 1.8975 | CL22: 20 | CM22: 3 | CN22: 3 | CT22: 21 | CU22: =CU21+0.05 -> 2
A23: 22 | B23: =B22*2 -> 1048576 | D23: V | E23: 3.44 | F23: volcano cape | H23: IV | I23: 1.2 | Y23: 21 | Z23: =Z22+0.02 -> 1.42 | AA23: 1.53 | AB23: 1.53 | AC23: 1.53 | CT23: 22 | CU23: =CU22+0.05 -> 2.05
A24: 23 | B24: =B23*2 -> 2097152 | H24: V | I24: 1.25 | Y24: 22 | Z24: =Z23+0.02 -> 1.44 | AA24: 1.55 | AB24: 1.55 | AC24: 1.55 | CT24: 23 | CU24: =CU23+0.05 -> 2.1
A25: 24 | B25: =B24*2 -> 4194304 | Y25: 23 | Z25: =Z24+0.02 -> 1.46 | AA25: 1.58 | AB25: 1.58 | AC25: 1.58 | CT25: 24 | CU25: =CU24+0.05 -> 2.15
A26: 25 | B26: =B25*2 -> 8388608 | Y26: 24 | Z26: =Z25+0.02 -> 1.48 | AA26: 1.6 | AB26: 1.6 | AC26: 1.6 | CT26: 25 | CU26: =CU25+0.05 -> 2.2
A27: 26 | B27: 16800000 | Y27: 25 | Z27: =Z26+0.02 -> 1.5 | AA27: 1.63 | AB27: 1.63 | AC27: 1.63 | CT27: 26 | CU27: =CU26+0.05 -> 2.25
A28: 27 | B28: =B27*2 -> 33600000 | Y28: 26 | Z28: =Z27+0.02 -> 1.52 | AA28: 1.65 | AB28: 1.65 | AC28: 1.65 | CT28: 27 | CU28: =CU27+0.05 -> 2.3
A29: 28 | B29: =B28*2 -> 67200000 | Y29: 27 | Z29: =Z28+0.02 -> 1.54 | AA29: 1.68 | AB29: 1.68 | AC29: 1.68 | CT29: 28 | CU29: =CU28+0.05 -> 2.35
A30: 29 | B30: =B29*2 -> 134400000 | Y30: 28 | Z30: =Z29+0.02 -> 1.56 | AA30: 1.7 | AB30: 1.7 | AC30: 1.7 | CT30: 29 | CU30: =CU29+0.05 -> 2.4
A31: 30 | B31: 537600000 | Y31: 29 | Z31: =Z30+0.02 -> 1.58 | AA31: 1.73 | AB31: 1.73 | AC31: 1.73 | CT31: 30 | CU31: =CU30+0.05 -> 2.45
A32: 31 | B32: =B31*2 -> 1075200000 | Y32: 30 | Z32: =Z31+0.02 -> 1.6 | AA32: 1.75 | AB32: 1.75 | AC32: 1.75 | CT32: 31 | CU32: =CU31+0.05 -> 2.5
A33: 32 | B33: 2150000000 | Y33: 31 | Z33: =Z32+0.02 -> 1.62 | AA33: 1.78 | AB33: 1.78 | AC33: 1.78 | CT33: 32 | CU33: =CU32+0.05 -> 2.55
A34: 33 | B34: 4310000000 | Y34: 32 | Z34: =Z33+0.02 -> 1.64 | AA34: 1.8 | AB34: 1.8 | AC34: 1.8 | CT34: 33 | CU34: =CU33+0.05 -> 2.6
A35: 34 | B35: =B34*2 -> 8620000000 | Y35: 33 | Z35: =Z34+0.02 -> 1.66 | AA35: 1.83 | AB35: 1.83 | AC35: 1.83 | CT35: 34 | CU35: =CU34+0.05 -> 2.65
A36: 35 | B36: 17240000000 | Y36: 34 | Z36: =Z35+0.02 -> 1.68 | AA36: 1.85 | AB36: 1.85 | AC36: 1.85 | CT36: 35 | CU36: =CU35+0.05 -> 2.7
A37: 36 | B37: 34480000000 | Y37: 35 | Z37: =Z36+0.02 -> 1.7 | AA37: 1.88 | AB37: 1.88 | AC37: 1.88 | CT37: 36 | CU37: =CU36+0.05 -> 2.75
Y38: 36 | Z38: =Z37+0.02 -> 1.72 | AA38: 1.9 | AB38: 1.9 | AC38: 1.9 | CT38: 37 | CU38: =CU37+0.05 -> 2.8
Y39: 37 | Z39: =Z38+0.02 -> 1.74 | AA39: 1.93 | AB39: 1.93 | AC39: 1.93 | CT39: 38 | CU39: =CU38+0.05 -> 2.85
Y40: 38 | Z40: =Z39+0.02 -> 1.76 | AA40: 1.95 | AB40: 1.95 | AC40: 1.95 | CT40: 39 | CU40: =CU39+0.05 -> 2.9
...

Sheet Max Power Per Click
A1: Max Power per click Calculator
A2: F2P - Plausible limit | F2: P2W - Plausible limit
B3: Note | C3: Multiplier | D3: Values | G3: Note | H3: Multiplier | I3: Values
A4: Awakening | B4: 36 | C4: 3,448 * 10^10 | D4: =CALCULAR(C4) -> 34480000000 | F4: Awakening | G4: 36 | H4: 3,448 * 10^10 | I4: =CALCULAR(H4) -> 34480000000
A5: Acessories | B5: All best secret + Evolve V | C5: 2,75^3 *2,88*3 * 1,25^5 | D5: =TRUNC(CALCULAR(C5),2) -> 548.35 | F5: Acessories | G5: All best secret | H5: 2,75^3 *2,88*3 * 1,25^5 | I5: =TRUNC(CALCULAR(H5),2) -> 548.35
A6: Index | B6: 9 worlds | C6: 1,1^9 | D6: =TRUNC(CALCULAR(C6),2) -> 2.35 | F6: Index | G6: 9 worlds | H6: 1,1^9 | I6: =TRUNC(CALCULAR(H6),2) -> 2.35
A7: Gacha | B7: Haki | C7: 10 | D7: =CALCULAR(C7) -> 10 | F7: Gacha | G7: Haki | H7: 10 | I7: =CALCULAR(H7) -> 10
B8: Race | C8: 10 | D8: =CALCULAR(C8) -> 10 | G8: Race | H8: 10 | I8: =CALCULAR(H8) -> 10
B9: Dragon Power | C9: 4 | D9: =CALCULAR(C9) -> 4 | G9: Dragon Power | H9: 4 | I9: =CALCULAR(H9) -> 4
B10: Slime Power | C10: 10 | D10: =CALCULAR(C10) -> 10 | G10: Slime Power | H10: 10 | I10: =CALCULAR(H10) -> 10
B11: Cursed Tecnique | C11: 10 | D11: =CALCULAR(C11) -> 10 | G11: Cursed Tecnique | H11: 10 | I11: =CALCULAR(H11) -> 10
B12: Cursed Spirit | C12: 10 | D12: =CALCULAR(C12) -> 10 | G12: Cursed Spirit | H12: 10 | I12: =CALCULAR(H12) -> 10
B13: Hunter Rank | C13: 10 | D13: 10 | G13: Hunter Rank | H13: 10 | I13: 10
A14: Progressions | B14: Fighting Style (W2) | C14: 3 | D14: =CALCULAR(C14) -> 3 | F14: Progressions | G14: Fighting Style (W2) | H14: 3 | I14: =CALCULAR(H14) -> 3
B15: Demon Lord (W5) | C15: 3.5 | D15: =CALCULAR(C15) -> 3.5 | G15: Demon Lord (W5) | H15: 3.5 | I15: =CALCULAR(H15) -> 3.5
B16: Domain (W7) | C16: 3.5 | D16: =CALCULAR(C16) -> 3.5 | G16: Domain (W7) | H16: 3.5 | I16: =CALCULAR(H16) -> 3.5
B17: System (W9) | C17: 3.5 | D17: =CALCULAR(C17) -> 3.5 | G17: System (W9) | H17: 3.5 | I17: =CALCULAR(H17) -> 3.5
A18: Swords | B18: Best sword ( Yoru) | C18: 5 | D18: =CALCULAR(C18) -> 5 | F18: Swords | G18: Best sword ( Yoru) 2x | H18: 5 ^ 2 | I18: =CALCULAR(H18) -> 25
B19: Enchant Punks | C19: 1.75 | D19: =CALCULAR(C19) -> 1.75 | G19: Enchant Punks | H19: 1,75^2 | I19: =CALCULAR(H19) -> 3.0625
A20: Fighters | B20: Best fighter (Kenpachi) | C20: 1.5 | D20: =CALCULAR(C20) -> 1.5 | F20: Fighters | G20: Best fighter (Kenpachi) | H20: 1,5^2 | I20: =CALCULAR(H20) -> 2.25
A21: Title | B21: Best title (King of Curses) | C21: 1.5 | D21: =CALCULAR(C21) -> 1.5 | F21: Title | G21: Best title (King of Curses) | H21: 1.5 | I21: =CALCULAR(H21) -> 1.5
A22: Avatars | B22: Best avatar (Monarch) | C22: 645.98 | D22: =CALCULAR(C22) -> 645.98 | F22: Avatars | G22: Best avatar (Monarch) | H22: 645.98 | I22: =CALCULAR(H22) -> 645.98
A23: Potions | B23: Power potions (Huge, Big, Small) | C23: 2,5*2 * 1,5 | D23: =CALCULAR(C23) -> 7.5 | F23: Potions | G23: Power potions (Huge, Big, Small) | H23: 2,5*2 * 1,5 | I23: =CALCULAR(H23) -> 7.5
A24: Side Quests | B24: All side quests | C24: 1,5^5 | D24: =TRUNC(CALCULAR(C24),2) -> 7.59 | F24: Side Quests | G24: All side quests | H24: 1,5^5 | I24: =TRUNC(CALCULAR(H24),2) -> 7.59
A25: Units | B25: All Monarch Shiny | C25: 12300*4 + 8200*3 | D25: =CALCULAR(C25) -> 73800 | F25: Units | G25: All Monarch Shiny | H25: 12300*5 + 8200*4 | I25: =CALCULAR(H25) -> 94300
B26: Best renames | C26: 1.75 | D26: =CALCULAR(C26) -> 1.75 | G26: Best renames | H26: 1.75 | I26: =CALCULAR(H26) -> 1.75
B27: Best passive | C27: 1.75 | D27: =CALCULAR(C27) -> 1.75 | G27: Best passive | H27: 1.75 | I27: =CALCULAR(H27) -> 1.75
B28: Max Arise | C28: 1.75 | D28: =CALCULAR(C28) -> 1.75 | G28: Max Arise | H28: 1.75 | I28: =CALCULAR(H28) -> 1.75
A29: Achievements | B29: Almost all achievements, ignoring Tempest invasion VIII+, clicks VIII+, trial medium VIII+ | D29: =CALCULAR(C29) | F29: Achievements | G29: Almost all achievements, ignoring Tempest invasion VIII+, clicks VIII+, trial medium VIII+ | I29: =CALCULAR(H29)
B30: Clicks (I - VIII) | C30: 1,1 ^ 6 * 1.15^3*1,20 | D30: =CALCULAR(C30) -> 3.2331874 | G30: Clicks (I - VIII) | H30: 1,1 ^ 6 * 1.15^3*1,20 | I30: =CALCULAR(H30) -> 3.2331874
B31: Star Open (I - VI) | C31: 1,1 ^ 6 | D31: =CALCULAR(C31) -> 1.771561 | G31: Star Open (I - VI) | H31: 1,1 ^ 6 | I31: =CALCULAR(H31) -> 1.771561
B32: Easy Trial ( III and VIII) | C32: 1,1 * 1.15 | D32: =CALCULAR(C32) -> 1.265 | G32: Easy Trial ( III and VIII) | H32: 1,1 * 1.15 | I32: =CALCULAR(H32) -> 1.265
B33: Medium Trial (III,VIII) | C33: 1,1*1,15 | D33: =CALCULAR(C33) -> 1.265 | G33: Medium Trial (III,VIII) | H33: 1,1*1,15 | I33: =CALCULAR(H33) -> 1.265
B34: Dragon Defense (III, VIII,XIII, XVIII) | C34: 1,1 *1.15*1.2*1.25 | D34: =CALCULAR(C34) -> 1.8975 | G34: Dragon Defense (III, VIII,XIII, XVIII) | H34: 1,1 *1.15*1.2*1.25 | I34: =CALCULAR(H34) -> 1.8975
B35: Tempest Invasion (III,VIII) | C35: 1,1*1,15 | D35: =CALCULAR(C35) -> 1.265 | G35: Tempest Invasion (III,VIII) | H35: 1,1*1,15 | I35: =CALCULAR(H35) -> 1.265
A36: Total | D36: =TRUNC(PRODUCT(D30:D35),2) -> 22 | F36: Total | I36: =TRUNC(PRODUCT(I30:I35),2) -> 22
A37: Trial/Tempest Upgrades | B37: Power upgrades | C37: 3 * 3 | D37: =CALCULAR(C37) -> 9 | F37: Trial/Tempest Upgrades | G37: Power upgrades | H37: 3 * 3 | I37: =CALCULAR(H37) -> 9
A38: Skill tree (world 2) | B38: Start, Power (1-5) and insane power (1-3) | C38: 2.4 | D38: =CALCULAR(C38) -> 2.4 | F38: Skill tree (world 2) | G38: Start, Power (1-5) and insane power (1-3) | H38: 2.4 | I38: =CALCULAR(H38) -> 2.4
A39: Skill tree (world 9) | B39: Start, Power (I -X) | C39: 3.5 | D39: =CALCULAR(C39) -> 3.5 | F39: Skill tree (world 9) | G39: Start, Power (I -X) | H39: 3.5 | I39: =CALCULAR(H39) -> 3.5
A40: Level | B40: Max its 50 but lets consider 44 | C40: 1+0,05*(50-1) | D40: =CALCULAR(C40) -> 3.45 | F40: Level | G40: Max (50) | H40: 1+0,05*(50-1) | I40: =CALCULAR(H40) -> 3.45
...
